Вопрос:
В этом задании в нашу функцию передаются два параметра: целочисленная переменная ("а") и некоторая функция ("func"). Вам необходимо запустить функцию "func", с переменной "а" в качестве аргумента. Но вот проблема - в функции, похоже, оказалась ошибка. Вам нужно возвратить имя (свойство "name") возникающей ошибки.

Ответ:
function testErrorFunc(a, func) {         
    try {
        return func(a);
    }catch(e) {
        return e.name;
    }
}